I'm sorry, but an uncaught exception occurred.

While running game code:
  File "game/script.rpy", line 28, in script
    e "You've created a new Ren'Py game."
Exception: Sayer 'e' is not defined.

-- Full Traceback ------------------------------------------------------------

Full traceback:
  File "game/script.rpy", line 28, in script
    e "You've created a new Ren'Py game."
  File "C:\Users\Daniel\Downloads\renpy-7.3.2-sdk\renpy\ast.py", line 676, in execute
    who = eval_who(self.who, self.who_fast)
  File "C:\Users\Daniel\Downloads\renpy-7.3.2-sdk\renpy\ast.py", line 574, in eval_who
    raise Exception("Sayer '%s' is not defined." % who.encode("utf-8"))
Exception: Sayer 'e' is not defined.

Windows-8-6.2.9200
Ren'Py 7.3.2.320
curprise_cult 1.0
Wed Oct 09 21:41:38 2019
